<mujoco model="ur5e">
  <compiler angle="radian" meshdir="assets/" texturedir="assets/"/>

  <asset>
    <mesh name="base" content_type="model/obj" file="full/base.obj"/>
    <mesh name="shoulder" content_type="model/obj" file="full/shoulder.obj"/>
    <mesh name="upperarm" content_type="model/obj" file="full/upperarm.obj"/>
    <mesh name="forearm" content_type="model/obj" file="full/forearm.obj"/>
    <mesh name="wrist1" content_type="model/obj" file="full/wrist1.obj"/>
    <mesh name="wrist2" content_type="model/obj" file="full/wrist2.obj"/>
    <mesh name="wrist3" content_type="model/obj" file="full/wrist3.obj"/>
  </asset>

  <worldbody>
    <geom pos="0 0 0" quat="-1 0 0 0" type="mesh" contype="0" conaffinity="0" group="1" density="0" mesh="base"/>
    <body name="shoulder_link" pos="0 0 0.1625" quat="0 0 0 1">
      <inertial pos="0 -0.00193 -0.02561" quat="0.560239 0.250606 -0.316559 0.72327" mass="3.761" diaginertia="0.00703079 0.0070003 0.00602478"/>
      <joint name="shoulder_pan_joint" pos="0 0 0" axis="0 0 1" range="-6.28319 6.28319" actuatorfrcrange="-150 150"/>
      <geom quat="0 0 0 1" type="mesh" contype="0" conaffinity="0" group="1" density="0" mesh="shoulder"/>
      <body name="upper_arm_link" quat="0.707107 0.707107 0 0">
        <inertial pos="-0.2125 0 0.11336" quat="0.500275 0.499641 0.500368 0.499716" mass="8.058" diaginertia="0.333881 0.332472 0.0150588"/>
        <joint name="shoulder_lift_joint" pos="0 0 0" axis="0 0 1" range="-6.28319 6.28319" actuatorfrcrange="-150 150"/>
        <geom pos="0 0 0.138" quat="0.5 0.5 -0.5 -0.5" type="mesh" contype="0" conaffinity="0" group="1" density="0" mesh="upperarm"/>
        <body name="forearm_link" pos="-0.425 0 0">
          <inertial pos="-0.2422 0 0.0265" quat="0.501301 0.498381 0.510711 0.489375" mass="2.846" diaginertia="0.0787927 0.0785102 0.00397103"/>
          <joint name="elbow_joint" pos="0 0 0" axis="0 0 1" range="-3.14159 3.14159" actuatorfrcrange="-150 150"/>
          <geom pos="0 0 0.007" quat="0.5 0.5 -0.5 -0.5" type="mesh" contype="0" conaffinity="0" group="1" density="0" mesh="forearm"/>
          <body name="wrist_1_link" pos="-0.3922 0 0.1333">
            <inertial pos="0 -0.01634 -0.0018" quat="0.960609 0.277707 0.00515042 -0.00913626" mass="1.37" diaginertia="0.00165502 0.00142363 0.00119868"/>
            <joint name="wrist_1_joint" pos="0 0 0" axis="0 0 1" range="-6.28319 6.28319" actuatorfrcrange="-28 28"/>
            <geom pos="0 0 -0.127" quat="0.707107 0.707107 0 0" type="mesh" contype="0" conaffinity="0" group="1" density="0" mesh="wrist1"/>
            <body name="wrist_2_link" pos="0 -0.0997 -2.04488e-11" quat="0.707107 0.707107 0 0">
              <inertial pos="0 0.01634 -0.0018" quat="0.996652 -0.0779336 -0.00684629 -0.0237381" mass="1.3" diaginertia="0.00135637 0.00128607 0.00095814"/>
              <joint name="wrist_2_joint" pos="0 0 0" axis="0 0 1" range="-6.28319 6.28319" actuatorfrcrange="-28 28"/>
              <geom pos="0 0 -0.0997" quat="1 0 0 0" type="mesh" contype="0" conaffinity="0" group="1" density="0" mesh="wrist2"/>
              <body name="wrist_3_link" pos="0 0.0996 -2.04283e-11" quat="0.707107 -0.707107 0 0">
                <inertial pos="0 0 -0.001159" quat="0.0048234 0.706235 -0.0143444 0.707816" mass="0.365" diaginertia="0.000257573 0.000189069 0.000186938"/>
                <joint name="wrist_3_joint" pos="0 0 0" axis="0 0 1" range="-6.28319 6.28319" actuatorfrcrange="-28 28"/>
                <geom pos="0 0 -0.0989" quat="0.707107 0.707107 0 0" type="mesh" contype="0" conaffinity="0" group="1" density="0" mesh="wrist3"/>
              </body>
            </body>
          </body>
        </body>
      </body>
    </body>
  </worldbody>
</mujoco>
