<mujoco model="ur5e">
  <compiler angle="radian" meshdir="assets/" texturedir="assets/"/>
  <asset>
    <mesh file="full/base/base_0.obj" scale="1.0 1.0 1.0"/>
    <mesh file="full/base/base_1.obj" scale="1.0 1.0 1.0"/>
    <material name="material_base_0" specular="0.20000000000000004" shininess="1.0" rgba="0.27843137 0.27843137 0.27843137 1.0"/>
    <material name="material_base_1" specular="0.20000000000000004" shininess="1.0" rgba="0.03137255 0.03137255 0.03137255 1.0"/>
    <mesh file="full/shoulder/shoulder_0.obj" scale="1.0 1.0 1.0"/>
    <mesh file="full/shoulder/shoulder_1.obj" scale="1.0 1.0 1.0"/>
    <mesh file="full/shoulder/shoulder_2.obj" scale="1.0 1.0 1.0"/>
    <material name="material_shoulder_0" specular="0.20000000000000004" shininess="1.0" rgba="0.27843137 0.27843137 0.27843137 1.0"/>
    <material name="material_shoulder_1" specular="0.20000000000000004" shininess="1.0" rgba="0.03137255 0.03137255 0.03137255 1.0"/>
    <material name="material_shoulder_2" specular="0.20000000000000004" shininess="1.0" rgba="0.49019608 0.67843137 0.80000000 1.0"/>
    <mesh file="full/upperarm/upperarm_0.obj" scale="1.0 1.0 1.0"/>
    <mesh file="full/upperarm/upperarm_1.obj" scale="1.0 1.0 1.0"/>
    <mesh file="full/upperarm/upperarm_2.obj" scale="1.0 1.0 1.0"/>
    <mesh file="full/upperarm/upperarm_3.obj" scale="1.0 1.0 1.0"/>
    <material name="material_upperarm_0" specular="0.20000000000000004" shininess="1.0" rgba="0.49019608 0.67843137 0.80000000 1.0"/>
    <material name="material_upperarm_1" specular="0.20000000000000004" shininess="1.0" rgba="0.27843137 0.27843137 0.27843137 1.0"/>
    <material name="material_upperarm_2" specular="0.20000000000000004" shininess="1.0" rgba="0.03137255 0.03137255 0.03137255 1.0"/>
    <material name="material_upperarm_3" specular="0.20000000000000004" shininess="1.0" rgba="0.81960784 0.81960784 0.81960784 1.0"/>
    <mesh file="full/forearm/forearm_0.obj" scale="1.0 1.0 1.0"/>
    <mesh file="full/forearm/forearm_1.obj" scale="1.0 1.0 1.0"/>
    <mesh file="full/forearm/forearm_2.obj" scale="1.0 1.0 1.0"/>
    <mesh file="full/forearm/forearm_3.obj" scale="1.0 1.0 1.0"/>
    <material name="material_forearm_0" specular="0.20000000000000004" shininess="1.0" rgba="0.27843137 0.27843137 0.27843137 1.0"/>
    <material name="material_forearm_1" specular="0.20000000000000004" shininess="1.0" rgba="0.03137255 0.03137255 0.03137255 1.0"/>
    <material name="material_forearm_2" specular="0.20000000000000004" shininess="1.0" rgba="0.81960784 0.81960784 0.81960784 1.0"/>
    <material name="material_forearm_3" specular="0.20000000000000004" shininess="1.0" rgba="0.49019608 0.67843137 0.80000000 1.0"/>
    <mesh file="full/wrist1/wrist1_0.obj" scale="1.0 1.0 1.0"/>
    <mesh file="full/wrist1/wrist1_1.obj" scale="1.0 1.0 1.0"/>
    <mesh file="full/wrist1/wrist1_2.obj" scale="1.0 1.0 1.0"/>
    <material name="material_wrist1_0" specular="0.20000000000000004" shininess="1.0" rgba="0.27843137 0.27843137 0.27843137 1.0"/>
    <material name="material_wrist1_1" specular="0.20000000000000004" shininess="1.0" rgba="0.49019608 0.67843137 0.80000000 1.0"/>
    <material name="material_wrist1_2" specular="0.20000000000000004" shininess="1.0" rgba="0.03137255 0.03137255 0.03137255 1.0"/>
    <mesh file="full/wrist2/wrist2_0.obj" scale="1.0 1.0 1.0"/>
    <mesh file="full/wrist2/wrist2_1.obj" scale="1.0 1.0 1.0"/>
    <mesh file="full/wrist2/wrist2_2.obj" scale="1.0 1.0 1.0"/>
    <material name="material_wrist2_0" specular="0.20000000000000004" shininess="1.0" rgba="0.27843137 0.27843137 0.27843137 1.0"/>
    <material name="material_wrist2_1" specular="0.20000000000000004" shininess="1.0" rgba="0.49019608 0.67843137 0.80000000 1.0"/>
    <material name="material_wrist2_2" specular="0.20000000000000004" shininess="1.0" rgba="0.03137255 0.03137255 0.03137255 1.0"/>
    <mesh file="full/wrist3/wrist3.obj" scale="1.0 1.0 1.0"/>
    <material name="material_wrist3_0" specular="0.20000000000000004" shininess="1.0" rgba="0.81960784 0.81960784 0.81960784 1.0"/>
  </asset>
  <worldbody>
    <body name="shoulder_link" pos="0 0 0.1625" quat="0 0 0 1">
      <inertial pos="0 -0.00193 -0.02561" quat="0.560239 0.250606 -0.316559 0.72327" mass="3.761" diaginertia="0.00703079 0.0070003 0.00602478"/>
      <joint name="shoulder_pan_joint" pos="0 0 0" axis="0 0 1" range="-6.28319 6.28319" actuatorfrcrange="-150 150"/>
      <body name="upper_arm_link" quat="0.707107 0.707107 0 0">
        <inertial pos="-0.2125 0 0.11336" quat="0.500275 0.499641 0.500368 0.499716" mass="8.058" diaginertia="0.333881 0.332472 0.0150588"/>
        <joint name="shoulder_lift_joint" pos="0 0 0" axis="0 0 1" range="-6.28319 6.28319" actuatorfrcrange="-150 150"/>
        <body name="forearm_link" pos="-0.425 0 0">
          <inertial pos="-0.2422 0 0.0265" quat="0.501301 0.498381 0.510711 0.489375" mass="2.846" diaginertia="0.0787927 0.0785102 0.00397103"/>
          <joint name="elbow_joint" pos="0 0 0" axis="0 0 1" range="-3.14159 3.14159" actuatorfrcrange="-150 150"/>
          <body name="wrist_1_link" pos="-0.3922 0 0.1333">
            <inertial pos="0 -0.01634 -0.0018" quat="0.960609 0.277707 0.00515042 -0.00913626" mass="1.37" diaginertia="0.00165502 0.00142363 0.00119868"/>
            <joint name="wrist_1_joint" pos="0 0 0" axis="0 0 1" range="-6.28319 6.28319" actuatorfrcrange="-28 28"/>
            <body name="wrist_2_link" pos="0 -0.0997 -2.04488e-11" quat="0.707107 0.707107 0 0">
              <inertial pos="0 0.01634 -0.0018" quat="0.996652 -0.0779336 -0.00684629 -0.0237381" mass="1.3" diaginertia="0.00135637 0.00128607 0.00095814"/>
              <joint name="wrist_2_joint" pos="0 0 0" axis="0 0 1" range="-6.28319 6.28319" actuatorfrcrange="-28 28"/>
              <body name="wrist_3_link" pos="0 0.0996 -2.04283e-11" quat="0.707107 -0.707107 0 0">
                <inertial pos="0 0 -0.001159" quat="0.0048234 0.706235 -0.0143444 0.707816" mass="0.365" diaginertia="0.000257573 0.000189069 0.000186938"/>
                <joint name="wrist_3_joint" pos="0 0 0" axis="0 0 1" range="-6.28319 6.28319" actuatorfrcrange="-28 28"/>
                <geom material="material_wrist3_0" mesh="wrist3" class="visual" pos="0 0 -0.0989" quat="0.707107 0.707107 0 0"/>
                <geom mesh="wrist3" class="collision" pos="0 0 -0.0989" quat="0.707107 0.707107 0 0"/>
                <site name="wrist_3_link" pos="0 0 0" quat="1.0 0 0 0"/>
                <site name="ft_frame" pos="0 0 0" quat="0 1.0 0 0"/>
                <site name="flange" pos="0 0 0" quat="-0.5000000000000001 0.5 0.5000000000000001 0.49999999999999994"/>
                <site name="tool0" pos="0 0 0" quat="1.0 0 0 0"/>
              </body>
              <geom mesh="wrist2_0" material="material_wrist2_2" class="visual" pos="0 0 -0.0997" quat="1 0 0 0"/>
              <geom mesh="wrist2_1" material="material_wrist2_1" class="visual" pos="0 0 -0.0997" quat="1 0 0 0"/>
              <geom mesh="wrist2_2" material="material_wrist2_0" class="visual" pos="0 0 -0.0997" quat="1 0 0 0"/>
              <geom mesh="wrist2_0" class="collision" pos="0 0 -0.0997" quat="1 0 0 0"/>
              <geom mesh="wrist2_1" class="collision" pos="0 0 -0.0997" quat="1 0 0 0"/>
              <geom mesh="wrist2_2" class="collision" pos="0 0 -0.0997" quat="1 0 0 0"/>
              <site name="wrist_2_link" pos="0 0 0" quat="1.0 0 0 0"/>
            </body>
            <geom mesh="wrist1_0" material="material_wrist1_2" class="visual" pos="0 0 -0.127" quat="0.707107 0.707107 0 0"/>
            <geom mesh="wrist1_1" material="material_wrist1_1" class="visual" pos="0 0 -0.127" quat="0.707107 0.707107 0 0"/>
            <geom mesh="wrist1_2" material="material_wrist1_0" class="visual" pos="0 0 -0.127" quat="0.707107 0.707107 0 0"/>
            <geom mesh="wrist1_0" class="collision" pos="0 0 -0.127" quat="0.707107 0.707107 0 0"/>
            <geom mesh="wrist1_1" class="collision" pos="0 0 -0.127" quat="0.707107 0.707107 0 0"/>
            <geom mesh="wrist1_2" class="collision" pos="0 0 -0.127" quat="0.707107 0.707107 0 0"/>
            <site name="wrist_1_link" pos="0 0 0" quat="1.0 0 0 0"/>
          </body>
          <geom mesh="forearm_0" material="material_forearm_3" class="visual" pos="0 0 0.007" quat="0.5 0.5 -0.5 -0.5"/>
          <geom mesh="forearm_1" material="material_forearm_2" class="visual" pos="0 0 0.007" quat="0.5 0.5 -0.5 -0.5"/>
          <geom mesh="forearm_2" material="material_forearm_1" class="visual" pos="0 0 0.007" quat="0.5 0.5 -0.5 -0.5"/>
          <geom mesh="forearm_3" material="material_forearm_0" class="visual" pos="0 0 0.007" quat="0.5 0.5 -0.5 -0.5"/>
          <geom mesh="forearm_0" class="collision" pos="0 0 0.007" quat="0.5 0.5 -0.5 -0.5"/>
          <geom mesh="forearm_1" class="collision" pos="0 0 0.007" quat="0.5 0.5 -0.5 -0.5"/>
          <geom mesh="forearm_2" class="collision" pos="0 0 0.007" quat="0.5 0.5 -0.5 -0.5"/>
          <geom mesh="forearm_3" class="collision" pos="0 0 0.007" quat="0.5 0.5 -0.5 -0.5"/>
          <site name="forearm_link" pos="0 0 0" quat="1.0 0 0 0"/>
        </body>
        <geom mesh="upperarm_0" material="material_upperarm_3" class="visual" pos="0 0 0.138" quat="0.5 0.5 -0.5 -0.5"/>
        <geom mesh="upperarm_1" material="material_upperarm_2" class="visual" pos="0 0 0.138" quat="0.5 0.5 -0.5 -0.5"/>
        <geom mesh="upperarm_2" material="material_upperarm_1" class="visual" pos="0 0 0.138" quat="0.5 0.5 -0.5 -0.5"/>
        <geom mesh="upperarm_3" material="material_upperarm_0" class="visual" pos="0 0 0.138" quat="0.5 0.5 -0.5 -0.5"/>
        <geom mesh="upperarm_0" class="collision" pos="0 0 0.138" quat="0.5 0.5 -0.5 -0.5"/>
        <geom mesh="upperarm_1" class="collision" pos="0 0 0.138" quat="0.5 0.5 -0.5 -0.5"/>
        <geom mesh="upperarm_2" class="collision" pos="0 0 0.138" quat="0.5 0.5 -0.5 -0.5"/>
        <geom mesh="upperarm_3" class="collision" pos="0 0 0.138" quat="0.5 0.5 -0.5 -0.5"/>
        <site name="upper_arm_link" pos="0 0 0" quat="1.0 0 0 0"/>
      </body>
      <geom mesh="shoulder_0" material="material_shoulder_2" class="visual" pos="" quat="0 0 0 1"/>
      <geom mesh="shoulder_1" material="material_shoulder_1" class="visual" pos="" quat="0 0 0 1"/>
      <geom mesh="shoulder_2" material="material_shoulder_0" class="visual" pos="" quat="0 0 0 1"/>
      <geom mesh="shoulder_0" class="collision" pos="" quat="0 0 0 1"/>
      <geom mesh="shoulder_1" class="collision" pos="" quat="0 0 0 1"/>
      <geom mesh="shoulder_2" class="collision" pos="" quat="0 0 0 1"/>
      <site name="shoulder_link" pos="0 0 0" quat="1.0 0 0 0"/>
    </body>
    <geom mesh="base_0" material="material_base_1" class="visual" pos="0 0 0" quat="-1 0 0 0"/>
    <geom mesh="base_1" material="material_base_0" class="visual" pos="0 0 0" quat="-1 0 0 0"/>
    <geom mesh="base_0" class="collision" pos="0 0 0" quat="-1 0 0 0"/>
    <geom mesh="base_1" class="collision" pos="0 0 0" quat="-1 0 0 0"/>
    <site name="world" pos="0 0 0" quat="1.0 0 0 0"/>
    <site name="base_link" pos="0 0 0" quat="1.0 0 0 0"/>
    <site name="base_link_inertia" pos="0 0 0" quat="0 0 0 1.0"/>
    <site name="base" pos="0 0 0" quat="0 0 0 1.0"/>
  </worldbody>
  <option integrator="implicitfast"/>
  <default>
    <default class="visual">
      <geom group="2" type="mesh" contype="0" conaffinity="0"/>
    </default>
    <default class="collision">
      <geom group="3" type="mesh"/>
    </default>
  </default>
  <sensor>
    <force name="fts_sensor_force" site="ft_frame"/>
    <torque name="fts_sensor_torque" site="ft_frame"/>
  </sensor>
  <default>
    <default class="ur5e">
      <general gaintype="fixed" biastype="affine" ctrlrange="-6.2831 6.2831" gainprm="2000" biasprm="0 -2000 -400" forcerange="-150 150"/>
      <default class="size3">
        <default class="size3_limited">
          <general ctrlrange="-3.1415 3.1415"/>
        </default>
      </default>
      <default class="size1">
        <general gainprm="500" biasprm="0 -500 -100" forcerange="-28 28"/>
      </default>
    </default>
  </default>
  <actuator>
    <general class="size3" name="shoulder_pan_joint" joint="shoulder_pan_joint"/>
    <general class="size3" name="shoulder_lift_joint" joint="shoulder_lift_joint"/>
    <general class="size3_limited" name="elbow_joint" joint="elbow_joint"/>
    <general class="size1" name="wrist_1_joint" joint="wrist_1_joint"/>
    <general class="size1" name="wrist_2_joint" joint="wrist_2_joint"/>
    <general class="size1" name="wrist_3_joint" joint="wrist_3_joint"/>
  </actuator>
</mujoco>